Workbook

Sheet plan de producción
Q1: lleno manual | R1: lleno manual | S1: lleno manual | U1: lleno manual | V1: lleno manual | Y1: lleno manual | AE1: lleno manual | AH1: AVANCE:
A2: PREVIOS | P2: LUNES | R2: MARTES | T2: MIERCOLES | U2: JUEVES | V2: VIERNES | Z2: Precio catálogo | AA2: Arrastrar | AB2: Arrastrar | AC2: Arrastrar | AH2: 1. Material | AI2: 2. ARMAR | AJ2: 3. Resoldar | AK2: 4. Pulir | AL2: 5. Pintar | AM2: 6. Ensamblar | AN2: 7. Empacar | AO2: Enviado
AA3: 0.3 | AD3: 0 | AF3: DIA A TERMINAR: | AH3: 20 | AI3: 40 | AJ3: 50 | AK3: 70 | AL3: 80 | AM3: 90 | AN3: 100
N4: Avance %: | O4: imp. | P4: Estado /sitio | Q4: COTI. | R4: CLIENTE | S4: Cod. equip. | T4: Equipo | U4: color | V4: CIUDAD | W4: LINEA | Y4: VENTA Antes de Iva | Z4: (ref. automática) | AA4: Horas max totales a invertir: | AB4: Horas faltantes x invertir: | AC4: dias hom faltantes x invertir: | AD4: Acum. a invertir | AE4: Quien: | AF4: Ofrecido: | AG4: Actualizado:
N5: 1 | P5: 1 | Q5: 3 | R5: JHON - NICOLAS | S5: XM161 | T5: Rack Sentadilla | U5: AZUL OSCURO | V5: Pereira | W5: musculación | Y5: 1990000 | Z5: =IFERROR(VLOOKUP(S5,'Precios y materiales '!$A:$C,3,FALSE),"") -> 1990000 | AA5: =(Y5*$AA$3)/'Mano de obra'!$C$9 -> 27.112241 | AB5: =AA5*(1-N5) -> 0 | AC5: =AB5/9 -> 0 | AD5: =AD3+(AA5*(1-N5)) -> 0 | AF5: 4 may | AG5: =IFERROR(TEXT(HLOOKUP(AD5,'Mano de obra'!$L$23:$BP$25,3,TRUE),"d mmm"),"") -> 27 May | AH5: =IF((($N5)*100)>='plan de producción'!AH$3,"x"," Material") -> x | AI5: =IF((($N5)*100)>='plan de producción'!AI$3,"x","Armar ") -> x | AJ5: =IF((($N5)*100)>='plan de producción'!AJ$3,"x"," Resoldar") -> x | AK5: =IF((($N5)*100)>='plan de producción'!AK$3,"x"," Pulir") -> x | AL5: =IF((($N5)*100)>='plan de producción'!AL$3,"x","Pintar ") -> x | AM5: =IF((($N5)*100)>='plan de producción'!AM$3,"x","Ensamblar ") -> x | AN5: =IF((($N5)*100)>='plan de producción'!AN$3,"x"," Empacar") -> x
M6: Cojines | N6: 1 | P6: 2 | Q6: 10 | R6: JHON - NICOLAS | S6: XM104 | T6: Banco hombro peso libre | U6: AZUL OSCURO | V6: Pereira | W6: musculación | Y6: 650000 | Z6: =IFERROR(VLOOKUP(S6,'Precios y materiales '!$A:$C,3,FALSE),"") -> 650000 | AA6: =(Y6*$AA$3)/'Mano de obra'!$C$9 -> 8.855757 | AB6: =AA6*(1-N6) -> 0 | AC6: =AB6/9 -> 0 | AD6: =AD5+(AA6*(1-N6)) -> 0 | AF6: 4 may | AG6: =IFERROR(TEXT(HLOOKUP(AD6,'Mano de obra'!$L$23:$BP$25,3,TRUE),"d mmm"),"") -> 27 May | AH6: =IF((($N6)*100)>='plan de producción'!AH$3,"x"," Material") -> x | AI6: =IF((($N6)*100)>='plan de producción'!AI$3,"x","Armar ") -> x | AJ6: =IF((($N6)*100)>='plan de producción'!AJ$3,"x"," Resoldar") -> x | AK6: =IF((($N6)*100)>='plan de producción'!AK$3,"x"," Pulir") -> x | AL6: =IF((($N6)*100)>='plan de producción'!AL$3,"x","Pintar ") -> x | AM6: =IF((($N6)*100)>='plan de producción'!AM$3,"x","Ensamblar ") -> x | AN6: =IF((($N6)*100)>='plan de producción'!AN$3,"x"," Empacar") -> x
M7: Cojines | N7: 1 | P7: 3 | Q7: 974 | R7: JHON - NICOLAS | S7: XM104 | T7: Banco hombro peso libre | U7: AZUL OSCURO | V7: Pereira | W7: musculación | Y7: 650000 | Z7: =IFERROR(VLOOKUP(S7,'Precios y materiales '!$A:$C,3,FALSE),"") -> 650000 | AA7: =(Y7*$AA$3)/'Mano de obra'!$C$9 -> 8.855757 | AB7: =AA7*(1-N7) -> 0 | AC7: =AB7/9 -> 0 | AD7: =AD6+(AA7*(1-N7)) -> 0 | AF7: 5 may | AG7: =IFERROR(TEXT(HLOOKUP(AD7,'Mano de obra'!$L$23:$BP$25,3,TRUE),"d mmm"),"") -> 27 May | AH7: =IF((($N7)*100)>='plan de producción'!AH$3,"x"," Material") -> x | AI7: =IF((($N7)*100)>='plan de producción'!AI$3,"x","Armar ") -> x | AJ7: =IF((($N7)*100)>='plan de producción'!AJ$3,"x"," Resoldar") -> x | AK7: =IF((($N7)*100)>='plan de producción'!AK$3,"x"," Pulir") -> x | AL7: =IF((($N7)*100)>='plan de producción'!AL$3,"x","Pintar ") -> x | AM7: =IF((($N7)*100)>='plan de producción'!AM$3,"x","Ensamblar ") -> x | AN7: =IF((($N7)*100)>='plan de producción'!AN$3,"x"," Empacar") -> x
M8: Cojines | N8: 1 | P8: 4 | Q8: 977 | R8: JHON - NICOLAS | S8: XM165 | T8: Sentadilla Bulgara | U8: AZUL OSCURO | V8: Pereira | W8: musculación | Y8: 490000 | Z8: =IFERROR(VLOOKUP(S8,'Precios y materiales '!$A:$C,3,FALSE),"") -> 490000 | AA8: =(Y8*$AA$3)/'Mano de obra'!$C$9 -> 6.6758783 | AB8: =AA8*(1-N8) -> 0 | AC8: =AB8/9 -> 0 | AD8: =AD7+(AA8*(1-N8)) -> 0 | AF8: 5 may | AG8: =IFERROR(TEXT(HLOOKUP(AD8,'Mano de obra'!$L$23:$BP$25,3,TRUE),"d mmm"),"") -> 27 May | AH8: =IF((($N8)*100)>='plan de producción'!AH$3,"x"," Material") -> x | AI8: =IF((($N8)*100)>='plan de producción'!AI$3,"x","Armar ") -> x | AJ8: =IF((($N8)*100)>='plan de producción'!AJ$3,"x"," Resoldar") -> x | AK8: =IF((($N8)*100)>='plan de producción'!AK$3,"x"," Pulir") -> x | AL8: =IF((($N8)*100)>='plan de producción'!AL$3,"x","Pintar ") -> x | AM8: =IF((($N8)*100)>='plan de producción'!AM$3,"x","Ensamblar ") -> x | AN8: =IF((($N8)*100)>='plan de producción'!AN$3,"x"," Empacar") -> x
M9: Cojines | N9: 0.9 | P9: 5 | Q9: 5 | R9: JHON - NICOLAS | S9: XM108 | T9: banco olimpico plano | U9: AZUL OSCURO | V9: Pereira | W9: musculación | Y9: 1490000 | Z9: =IFERROR(VLOOKUP(S9,'Precios y materiales '!$A:$C,3,FALSE),"") -> 1490000 | AA9: =(Y9*$AA$3)/'Mano de obra'!$C$9 -> 20.30012 | AB9: =AA9*(1-N9) -> 2.030012 | AC9: =AB9/9 -> 0.22555689 | AD9: =AD8+(AA9*(1-N9)) -> 2.030012 | AF9: 5 may | AG9: =IFERROR(TEXT(HLOOKUP(AD9,'Mano de obra'!$L$23:$BP$25,3,TRUE),"d mmm"),"") -> 27 May | AH9: =IF((($N9)*100)>='plan de producción'!AH$3,"x"," Material") -> x | AI9: =IF((($N9)*100)>='plan de producción'!AI$3,"x","Armar ") -> x | AJ9: =IF((($N9)*100)>='plan de producción'!AJ$3,"x"," Resoldar") -> x | AK9: =IF((($N9)*100)>='plan de producción'!AK$3,"x"," Pulir") -> x | AL9: =IF((($N9)*100)>='plan de producción'!AL$3,"x","Pintar ") -> x | AM9: =IF((($N9)*100)>='plan de producción'!AM$3,"x","Ensamblar ") -> x | AN9: =IF((($N9)*100)>='plan de producción'!AN$3,"x"," Empacar") -> Empacar
B10: Torno E. | M10: Cojines | N10: 1 | P10: 6 | Q10: 1 | R10: JHON - NICOLAS | S10: XM105 | T10: Banco Multifunción | U10: AZUL OSCURO | V10: Pereira | W10: musculación | Y10: 1190000 | Z10: =IFERROR(VLOOKUP(S10,'Precios y materiales '!$A:$C,3,FALSE),"") -> 1190000 | AA10: =(Y10*$AA$3)/'Mano de obra'!$C$9 -> 16.212847 | AB10: =AA10*(1-N10) -> 0 | AC10: =AB10/9 -> 0 | AD10: =AD9+(AA10*(1-N10)) -> 2.030012 | AF10: 5 may | AG10: =IFERROR(TEXT(HLOOKUP(AD10,'Mano de obra'!$L$23:$BP$25,3,TRUE),"d mmm"),"") -> 27 May | AH10: =IF((($N10)*100)>='plan de producción'!AH$3,"x"," Material") -> x | AI10: =IF((($N10)*100)>='plan de producción'!AI$3,"x","Armar ") -> x | AJ10: =IF((($N10)*100)>='plan de producción'!AJ$3,"x"," Resoldar") -> x | AK10: =IF((($N10)*100)>='plan de producción'!AK$3,"x"," Pulir") -> x | AL10: =IF((($N10)*100)>='plan de producción'!AL$3,"x","Pintar ") -> x | AM10: =IF((($N10)*100)>='plan de producción'!AM$3,"x","Ensamblar ") -> x | AN10: =IF((($N10)*100)>='plan de producción'!AN$3,"x"," Empacar") -> x
B11: Torno E. | M11: Cojines | N11: 1 | P11: 7 | Q11: 975 | R11: JHON - NICOLAS | S11: XM105 | T11: Banco Multifunción | U11: AZUL OSCURO | V11: Pereira | W11: musculación | Y11: 1190000 | Z11: =IFERROR(VLOOKUP(S11,'Precios y materiales '!$A:$C,3,FALSE),"") -> 1190000 | AA11: =(Y11*$AA$3)/'Mano de obra'!$C$9 -> 16.212847 | AB11: =AA11*(1-N11) -> 0 | AC11: =AB11/9 -> 0 | AD11: =AD10+(AA11*(1-N11)) -> 2.030012 | AF11: 5 may | AG11: =IFERROR(TEXT(HLOOKUP(AD11,'Mano de obra'!$L$23:$BP$25,3,TRUE),"d mmm"),"") -> 27 May | AH11: =IF((($N11)*100)>='plan de producción'!AH$3,"x"," Material") -> x | AI11: =IF((($N11)*100)>='plan de producción'!AI$3,"x","Armar ") -> x | AJ11: =IF((($N11)*100)>='plan de producción'!AJ$3,"x"," Resoldar") -> x | AK11: =IF((($N11)*100)>='plan de producción'!AK$3,"x"," Pulir") -> x | AL11: =IF((($N11)*100)>='plan de producción'!AL$3,"x","Pintar ") -> x | AM11: =IF((($N11)*100)>='plan de producción'!AM$3,"x","Ensamblar ") -> x | AN11: =IF((($N11)*100)>='plan de producción'!AN$3,"x"," Empacar") -> x
B12: Torno E. | M12: Cojines | N12: 1 | P12: 8 | Q12: 976 | R12: JHON - NICOLAS | S12: XM105 | T12: Banco Multifunción | U12: AZUL OSCURO | V12: Pereira | W12: musculación | Y12: 1190000 | Z12: =IFERROR(VLOOKUP(S12,'Precios y materiales '!$A:$C,3,FALSE),"") -> 1190000 | AA12: =(Y12*$AA$3)/'Mano de obra'!$C$9 -> 16.212847 | AB12: =AA12*(1-N12) -> 0 | AC12: =AB12/9 -> 0 | AD12: =AD11+(AA12*(1-N12)) -> 2.030012 | AF12: 6 may | AG12: =IFERROR(TEXT(HLOOKUP(AD12,'Mano de obra'!$L$23:$BP$25,3,TRUE),"d mmm"),"") -> 27 May | AH12: =IF((($N12)*100)>='plan de producción'!AH$3,"x"," Material") -> x | AI12: =IF((($N12)*100)>='plan de producción'!AI$3,"x","Armar ") -> x | AJ12: =IF((($N12)*100)>='plan de producción'!AJ$3,"x"," Resoldar") -> x | AK12: =IF((($N12)*100)>='plan de producción'!AK$3,"x"," Pulir") -> x | AL12: =IF((($N12)*100)>='plan de producción'!AL$3,"x","Pintar ") -> x | AM12: =IF((($N12)*100)>='plan de producción'!AM$3,"x","Ensamblar ") -> x | AN12: =IF((($N12)*100)>='plan de producción'!AN$3,"x"," Empacar") -> x
M13: Cojines | N13: 0.9 | P13: 9 | Q13: 13 | R13: JHON - NICOLAS | S13: XM111 | T13: Banco Predicador Libre | U13: AZUL OSCURO | V13: Pereira | W13: musculación | Y13: 1250000 | Z13: =IFERROR(VLOOKUP(S13,'Precios y materiales '!$A:$C,3,FALSE),"") -> 1250000 | AA13: =(Y13*$AA$3)/'Mano de obra'!$C$9 -> 17.030302 | AB13: =AA13*(1-N13) -> 1.7030302 | AC13: =AB13/9 -> 0.18922558 | AD13: =AD12+(AA13*(1-N13)) -> 3.7330422 | AF13: 6 may | AG13: =IFERROR(TEXT(HLOOKUP(AD13,'Mano de obra'!$L$23:$BP$25,3,TRUE),"d mmm"),"") -> 27 May | AH13: =IF((($N13)*100)>='plan de producción'!AH$3,"x"," Material") -> x | AI13: =IF((($N13)*100)>='plan de producción'!AI$3,"x","Armar ") -> x | AJ13: =IF((($N13)*100)>='plan de producción'!AJ$3,"x"," Resoldar") -> x | AK13: =IF((($N13)*100)>='plan de producción'!AK$3,"x"," Pulir") -> x | AL13: =IF((($N13)*100)>='plan de producción'!AL$3,"x","Pintar ") -> x | AM13: =IF((($N13)*100)>='plan de producción'!AM$3,"x","Ensamblar ") -> x | AN13: =IF((($N13)*100)>='plan de producción'!AN$3,"x"," Empacar") -> Empacar
B14: Torno E. | M14: Cojines | N14: 0.9 | P14: 10 | Q14: 12 | R14: JHON - NICOLAS | S14: XM130 | T14: Hammer remo | U14: AZUL OSCURO | V14: Pereira | W14: musculación | Y14: 2100000 | Z14: =IFERROR(VLOOKUP(S14,'Precios y materiales '!$A:$C,3,FALSE),"") -> 2100000 | AA14: =(Y14*$AA$3)/'Mano de obra'!$C$9 -> 28.610907 | AB14: =AA14*(1-N14) -> 2.8610907 | AC14: =AB14/9 -> 0.31789897 | AD14: =AD13+(AA14*(1-N14)) -> 6.5941329 | AF14: 6 may | AG14: =IFERROR(TEXT(HLOOKUP(AD14,'Mano de obra'!$L$23:$BP$25,3,TRUE),"d mmm"),"") -> 27 May | AH14: =IF((($N14)*100)>='plan de producción'!AH$3,"x"," Material") -> x | AI14: =IF((($N14)*100)>='plan de producción'!AI$3,"x","Armar ") -> x | AJ14: =IF((($N14)*100)>='plan de producción'!AJ$3,"x"," Resoldar") -> x | AK14: =IF((($N14)*100)>='plan de producción'!AK$3,"x"," Pulir") -> x | AL14: =IF((($N14)*100)>='plan de producción'!AL$3,"x","Pintar ") -> x | AM14: =IF((($N14)*100)>='plan de producción'!AM$3,"x","Ensamblar ") -> x | AN14: =IF((($N14)*100)>='plan de producción'!AN$3,"x"," Empacar") -> Empacar
B15: Torno E. | M15: Cojines | N15: 1 | P15: 11 | Q15: 42 | R15: JHON - NICOLAS | S15: XM162 | T15: Remo en punta | U15: AZUL OSCURO | V15: Pereira | W15: musculación | Y15: 1750000 | Z15: =IFERROR(VLOOKUP(S15,'Precios y materiales '!$A:$C,3,FALSE),"") -> 1750000 | AA15: =(Y15*$AA$3)/'Mano de obra'!$C$9 -> 23.842423 | AB15: =AA15*(1-N15) -> 0 | AC15: =AB15/9 -> 0 | AD15: =AD14+(AA15*(1-N15)) -> 6.5941329 | AF15: 7 may | AG15: =IFERROR(TEXT(HLOOKUP(AD15,'Mano de obra'!$L$23:$BP$25,3,TRUE),"d mmm"),"") -> 27 May | AH15: =IF((($N15)*100)>='plan de producción'!AH$3,"x"," Material") -> x | AI15: =IF((($N15)*100)>='plan de producción'!AI$3,"x","Armar ") -> x | AJ15: =IF((($N15)*100)>='plan de producción'!AJ$3,"x"," Resoldar") -> x | AK15: =IF((($N15)*100)>='plan de producción'!AK$3,"x"," Pulir") -> x | AL15: =IF((($N15)*100)>='plan de producción'!AL$3,"x","Pintar ") -> x | AM15: =IF((($N15)*100)>='plan de producción'!AM$3,"x","Ensamblar ") -> x | AN15: =IF((($N15)*100)>='plan de producción'!AN$3,"x"," Empacar") -> x
B16: Torno E. | M16: Cojines | N16: 1 | P16: 12 | Q16: 32 | R16: JHON - NICOLAS | S16: XM140 | T16: Pantorrillero | U16: AZUL OSCURO | V16: Pereira | W16: musculación | Y16: 1390000 | Z16: =IFERROR(VLOOKUP(S16,'Precios y materiales '!$A:$C,3,FALSE),"") -> 1390000 | AA16: =(Y16*$AA$3)/'Mano de obra'!$C$9 -> 18.937696 | AB16: =AA16*(1-N16) -> 0 | AC16: =AB16/9 -> 0 | AD16: =AD15+(AA16*(1-N16)) -> 6.5941329 | AF16: 7 may | AG16: =IFERROR(TEXT(HLOOKUP(AD16,'Mano de obra'!$L$23:$BP$25,3,TRUE),"d mmm"),"") -> 27 May | AH16: =IF((($N16)*100)>='plan de producción'!AH$3,"x"," Material") -> x | AI16: =IF((($N16)*100)>='plan de producción'!AI$3,"x","Armar ") -> x | AJ16: =IF((($N16)*100)>='plan de producción'!AJ$3,"x"," Resoldar") -> x | AK16: =IF((($N16)*100)>='plan de producción'!AK$3,"x"," Pulir") -> x | AL16: =IF((($N16)*100)>='plan de producción'!AL$3,"x","Pintar ") -> x | AM16: =IF((($N16)*100)>='plan de producción'!AM$3,"x","Ensamblar ") -> x | AN16: =IF((($N16)*100)>='plan de producción'!AN$3,"x"," Empacar") -> x
B17: Torno E. | M17: Cojines | N17: 0.7 | P17: 13 | Q17: 2 | R17: JHON - NICOLAS | S17: XM184 | T17: Prensa Atletica 3.0 lineal | U17: AZUL OSCURO | V17: Pereira | W17: musculación | Y17: 3990000 | Z17: =IFERROR(VLOOKUP(S17,'Precios y materiales '!$A:$C,3,FALSE),"") -> 3990000 | AA17: =(Y17*$AA$3)/'Mano de obra'!$C$9 -> 54.360723 | AB17: =AA17*(1-N17) -> 16.308217 | AC17: =AB17/9 -> 1.8120241 | AD17: =AD16+(AA17*(1-N17)) -> 22.90235 | AF17: 10 may | AG17: =IFERROR(TEXT(HLOOKUP(AD17,'Mano de obra'!$L$23:$BP$25,3,TRUE),"d mmm"),"") -> 27 May | AH17: =IF((($N17)*100)>='plan de producción'!AH$3,"x"," Material") -> x | AI17: =IF((($N17)*100)>='plan de producción'!AI$3,"x","Armar ") -> x | AJ17: =IF((($N17)*100)>='plan de producción'!AJ$3,"x"," Resoldar") -> x | AK17: =IF((($N17)*100)>='plan de producción'!AK$3,"x"," Pulir") -> x | AL17: =IF((($N17)*100)>='plan de producción'!AL$3,"x","Pintar ") -> Pintar | AM17: =IF((($N17)*100)>='plan de producción'!AM$3,"x","Ensamblar ") -> Ensamblar | AN17: =IF((($N17)*100)>='plan de producción'!AN$3,"x"," Empacar") -> Empacar
B18: Torno E. | M18: Cojines | N18: 0.9 | P18: 14 | Q18: 4 | R18: JHON - NICOLAS | S18: XM100 | T18: Abductor Aductor | U18: AZUL OSCURO | V18: Pereira | W18: musculación | Y18: 4000000 | Z18: =IFERROR(VLOOKUP(S18,'Precios y materiales '!$A:$C,3,FALSE),"") -> 4000000 | AA18: =(Y18*$AA$3)/'Mano de obra'!$C$9 -> 54.496966 | AB18: =AA18*(1-N18) -> 5.4496966 | AC18: =AB18/9 -> 0.60552184 | AD18: =AD17+(AA18*(1-N18)) -> 28.352047 | AF18: 10 may | AG18: =IFERROR(TEXT(HLOOKUP(AD18,'Mano de obra'!$L$23:$BP$25,3,TRUE),"d mmm"),"") -> 27 May | AH18: =IF((($N18)*100)>='plan de producción'!AH$3,"x"," Material") -> x | AI18: =IF((($N18)*100)>='plan de producción'!AI$3,"x","Armar ") -> x | AJ18: =IF((($N18)*100)>='plan de producción'!AJ$3,"x"," Resoldar") -> x | AK18: =IF((($N18)*100)>='plan de producción'!AK$3,"x"," Pulir") -> x | AL18: =IF((($N18)*100)>='plan de producción'!AL$3,"x","Pintar ") -> x | AM18: =IF((($N18)*100)>='plan de producción'!AM$3,"x","Ensamblar ") -> x | AN18: =IF((($N18)*100)>='plan de producción'!AN$3,"x"," Empacar") -> Empacar
N19: 0.5 | P19: 15 | Q19: 978 | R19: JHON - NICOLAS | S19: XC103 | T19: PIVOTE DE BARRA PARA JAULA | U19: AZUL OSCURO | V19: Pereira | W19: musculación | Y19: 168067.23 | Z19: =IFERROR(VLOOKUP(S19,'Precios y materiales '!$A:$C,3,FALSE),"") | AA19: =(Y19*$AA$3)/'Mano de obra'!$C$9 -> 2.2897885 | AB19: =AA19*(1-N19) -> 1.1448942 | AC19: =AB19/9 -> 0.12721047 | AD19: =AD18+(AA19*(1-N19)) -> 29.496941 | AF19: 10 may | AG19: =IFERROR(TEXT(HLOOKUP(AD19,'Mano de obra'!$L$23:$BP$25,3,TRUE),"d mmm"),"") -> 27 May | AH19: =IF((($N19)*100)>='plan de producción'!AH$3,"x"," Material") -> x | AI19: =IF((($N19)*100)>='plan de producción'!AI$3,"x","Armar ") -> x | AJ19: =IF((($N19)*100)>='plan de producción'!AJ$3,"x"," Resoldar") -> x | AK19: =IF((($N19)*100)>='plan de producción'!AK$3,"x"," Pulir") -> Pulir | AL19: =IF((($N19)*100)>='plan de producción'!AL$3,"x","Pintar ") -> Pintar | AM19: =IF((($N19)*100)>='plan de producción'!AM$3,"x","Ensamblar ") -> Ensamblar | AN19: =IF((($N19)*100)>='plan de producción'!AN$3,"x"," Empacar") -> Empacar
A20: Torno A. | N20: 0.2 | P20: 16 | Q20: 979 | R20: JHON - NICOLAS | S20: XC101 | T20: Accesorio fondos para jaula | U20: AZUL OSCURO | V20: Pereira | W20: musculación | Y20: 136974.79 | Z20: =IFERROR(VLOOKUP(S20,'Precios y materiales '!$A:$C,3,FALSE),"") | AA20: =(Y20*$AA$3)/'Mano de obra'!$C$9 -> 1.8661776 | AB20: =AA20*(1-N20) -> 1.4929421 | AC20: =AB20/9 -> 0.16588245 | AD20: =AD19+(AA20*(1-N20)) -> 30.989883 | AF20: 12 may | AG20: =IFERROR(TEXT(HLOOKUP(AD20,'Mano de obra'!$L$23:$BP$25,3,TRUE),"d mmm"),"") -> 27 May | AH20: =IF((($N20)*100)>='plan de producción'!AH$3,"x"," Material") -> x | AI20: =IF((($N20)*100)>='plan de producción'!AI$3,"x","Armar ") -> Armar | AJ20: =IF((($N20)*100)>='plan de producción'!AJ$3,"x"," Resoldar") -> Resoldar | AK20: =IF((($N20)*100)>='plan de producción'!AK$3,"x"," Pulir") -> Pulir | AL20: =IF((($N20)*100)>='plan de producción'!AL$3,"x","Pintar ") -> Pintar | AM20: =IF((($N20)*100)>='plan de producción'!AM$3,"x","Ensamblar ") -> Ensamblar | AN20: =IF((($N20)*100)>='plan de producción'!AN$3,"x"," Empacar") -> Empacar
A21: Torno A. | B21: Torno E. | M21: Cojines | N21: 0.2 | P21: 17 | Q21: 980 | R21: JHON - NICOLAS | S21: XM181 | T21: Jaula de Potencia para peso | U21: AZUL OSCURO | V21: Pereira | W21: musculación | Y21: 2880000 | Z21: =IFERROR(VLOOKUP(S21,'Precios y materiales '!$A:$C,3,FALSE),"") -> 2880000 | AA21: =(Y21*$AA$3)/'Mano de obra'!$C$9 -> 39.237815 | AB21: =AA21*(1-N21) -> 31.390252 | AC21: =AB21/9 -> 3.4878058 | AD21: =AD20+(AA21*(1-N21)) -> 62.380135 | AF21: 12 may | AG21: =IFERROR(TEXT(HLOOKUP(AD21,'Mano de obra'!$L$23:$BP$25,3,TRUE),"d mmm"),"") -> 27 May | AH21: =IF((($N21)*100)>='plan de producción'!AH$3,"x"," Material") -> x | AI21: =IF((($N21)*100)>='plan de producción'!AI$3,"x","Armar ") -> Armar | AJ21: =IF((($N21)*100)>='plan de producción'!AJ$3,"x"," Resoldar") -> Resoldar | AK21: =IF((($N21)*100)>='plan de producción'!AK$3,"x"," Pulir") -> Pulir | AL21: =IF((($N21)*100)>='plan de producción'!AL$3,"x","Pintar ") -> Pintar | AM21: =IF((($N21)*100)>='plan de producción'!AM$3,"x","Ensamblar ") -> Ensamblar | AN21: =IF((($N21)*100)>='plan de producción'!AN$3,"x"," Empacar") -> Empacar
A22: Torno A. | B22: Torno E. | M22: Cojines | N22: 0.8 | P22: 18 | Q22: 17 | R22: JHON - NICOLAS | S22: XM148 | T22: Polea Alta | U22: AZUL OSCURO | V22: Pereira | W22: musculación | Y22: 3890000 | Z22: =IFERROR(VLOOKUP(S22,'Precios y materiales '!$A:$C,3,FALSE),"") -> 3890000 | AA22: =(Y22*$AA$3)/'Mano de obra'!$C$9 -> 52.998299 | AB22: =AA22*(1-N22) -> 10.59966 | AC22: =AB22/9 -> 1.17774 | AD22: =AD21+(AA22*(1-N22)) -> 72.979795 | AF22: 13 may | AG22: =IFERROR(TEXT(HLOOKUP(AD22,'Mano de obra'!$L$23:$BP$25,3,TRUE),"d mmm"),"") -> 28 May | AH22: =IF((($N22)*100)>='plan de producción'!AH$3,"x"," Material") -> x | AI22: =IF((($N22)*100)>='plan de producción'!AI$3,"x","Armar ") -> x | AJ22: =IF((($N22)*100)>='plan de producción'!AJ$3,"x"," Resoldar") -> x | AK22: =IF((($N22)*100)>='plan de producción'!AK$3,"x"," Pulir") -> x | AL22: =IF((($N22)*100)>='plan de producción'!AL$3,"x","Pintar ") -> x | AM22: =IF((($N22)*100)>='plan de producción'!AM$3,"x","Ensamblar ") -> Ensamblar | AN22: =IF((($N22)*100)>='plan de producción'!AN$3,"x"," Empacar") -> Empacar
B23: Torno E. | M23: Cojines | N23: 0.2 | P23: 19 | Q23: 981 | R23: JHON - NICOLAS | S23: XM185 | T23: Sentadilla Hack Up 3.0 Lineal | U23: AZUL OSCURO | V23: Pereira | W23: musculación | Y23: 3990000 | Z23: =IFERROR(VLOOKUP(S23,'Precios y materiales '!$A:$C,3,FALSE),"") -> 3990000 | AA23: =(Y23*$AA$3)/'Mano de obra'!$C$9 -> 54.360723 | AB23: =AA23*(1-N23) -> 43.488579 | AC23: =AB23/9 -> 4.8320643 | AD23: =AD22+(AA23*(1-N23)) -> 116.46837 | AF23: 14 may | AG23: =IFERROR(TEXT(HLOOKUP(AD23,'Mano de obra'!$L$23:$BP$25,3,TRUE),"d mmm"),"") -> 28 May | AH23: =IF((($N23)*100)>='plan de producción'!AH$3,"x"," Material") -> x | AI23: =IF((($N23)*100)>='plan de producción'!AI$3,"x","Armar ") -> Armar | AJ23: =IF((($N23)*100)>='plan de producción'!AJ$3,"x"," Resoldar") -> Resoldar | AK23: =IF((($N23)*100)>='plan de producción'!AK$3,"x"," Pulir") -> Pulir | AL23: =IF((($N23)*100)>='plan de producción'!AL$3,"x","Pintar ") -> Pintar | AM23: =IF((($N23)*100)>='plan de producción'!AM$3,"x","Ensamblar ") -> Ensamblar | AN23: =IF((($N23)*100)>='plan de producción'!AN$3,"x"," Empacar") -> Empacar
A24: Torno A. | B24: Torno E. | N24: 0.9 | P24: 20 | Q24: 28 | R24: JHON - NICOLAS | S24: XM113 | T24: Crossover clásica | U24: AZUL OSCURO | V24: Pereira | W24: musculación | Y24: 5600000 | Z24: =IFERROR(VLOOKUP(S24,'Precios y materiales '!$A:$C,3,FALSE),"") -> 5600000 | AA24: =(Y24*$AA$3)/'Mano de obra'!$C$9 -> 76.295752 | AB24: =AA24*(1-N24) -> 7.6295752 | AC24: =AB24/9 -> 0.84773058 | AD24: =AD23+(AA24*(1-N24)) -> 124.09795 | AF24: 15 may | AG24: =IFERROR(TEXT(HLOOKUP(AD24,'Mano de obra'!$L$23:$BP$25,3,TRUE),"d mmm"),"") -> 31 May | AH24: =IF((($N24)*100)>='plan de producción'!AH$3,"x"," Material") -> x | AI24: =IF((($N24)*100)>='plan de producción'!AI$3,"x","Armar ") -> x | AJ24: =IF((($N24)*100)>='plan de producción'!AJ$3,"x"," Resoldar") -> x | AK24: =IF((($N24)*100)>='plan de producción'!AK$3,"x"," Pulir") -> x | AL24: =IF((($N24)*100)>='plan de producción'!AL$3,"x","Pintar ") -> x | AM24: =IF((($N24)*100)>='plan de producción'!AM$3,"x","Ensamblar ") -> x | AN24: =IF((($N24)*100)>='plan de producción'!AN$3,"x"," Empacar") -> Empacar
A25: Torno A. | B25: Torno E. | M25: Cojines | N25: 0.8 | P25: 21 | Q25: 16 | R25: JHON - NICOLAS | S25: XM145 | T25: Peck Deck doble función | U25: AZUL OSCURO | V25: Pereira | W25: musculación | Y25: 3990000 | Z25: =IFERROR(VLOOKUP(S25,'Precios y materiales '!$A:$C,3,FALSE),"") -> 3990000 | AA25: =(Y25*$AA$3)/'Mano de obra'!$C$9 -> 54.360723 | AB25: =AA25*(1-N25) -> 10.872145 | AC25: =AB25/9 -> 1.2080161 | AD25: =AD24+(AA25*(1-N25)) -> 134.97009 | AF25: 18 may | AG25: =IFERROR(TEXT(HLOOKUP(AD25,'Mano de obra'!$L$23:$BP$25,3,TRUE),"d mmm"),"") -> 31 May | AH25: =IF((($N25)*100)>='plan de producción'!AH$3,"x"," Material") -> x | AI25: =IF((($N25)*100)>='plan de producción'!AI$3,"x","Armar ") -> x | AJ25: =IF((($N25)*100)>='plan de producción'!AJ$3,"x"," Resoldar") -> x | AK25: =IF((($N25)*100)>='plan de producción'!AK$3,"x"," Pulir") -> x | AL25: =IF((($N25)*100)>='plan de producción'!AL$3,"x","Pintar ") -> x | AM25: =IF((($N25)*100)>='plan de producción'!AM$3,"x","Ensamblar ") -> Ensamblar | AN25: =IF((($N25)*100)>='plan de producción'!AN$3,"x"," Empacar") -> Empacar
N26: 1 | P26: 22 | Q26: 982 | R26: JHON - NICOLAS | S26: XM908 | T26: rack mancuernas 2 niveles | U26: AZUL OSCURO | V26: Pereira | W26: musculación | Y26: 500000 | Z26: =IFERROR(VLOOKUP(S26,'Precios y materiales '!$A:$C,3,FALSE),"") -> 600000 | AA26: =(Y26*$AA$3)/'Mano de obra'!$C$9 -> 6.8121207 | AB26: =AA26*(1-N26) -> 0 | AC26: =AB26/9 -> 0 | AD26: =AD25+(AA26*(1-N26)) -> 134.97009 | AF26: 18 may | AG26: =IFERROR(TEXT(HLOOKUP(AD26,'Mano de obra'!$L$23:$BP$25,3,TRUE),"d mmm"),"") -> 31 May | AH26: =IF((($N26)*100)>='plan de producción'!AH$3,"x"," Material") -> x | AI26: =IF((($N26)*100)>='plan de producción'!AI$3,"x","Armar ") -> x | AJ26: =IF((($N26)*100)>='plan de producción'!AJ$3,"x"," Resoldar") -> x | AK26: =IF((($N26)*100)>='plan de producción'!AK$3,"x"," Pulir") -> x | AL26: =IF((($N26)*100)>='plan de producción'!AL$3,"x","Pintar ") -> x | AM26: =IF((($N26)*100)>='plan de producción'!AM$3,"x","Ensamblar ") -> x | AN26: =IF((($N26)*100)>='plan de producción'!AN$3,"x"," Empacar") -> x
N27: 1 | P27: 23 | Q27: 983 | R27: JHON - NICOLAS | S27: XM908 | T27: rack mancuernas 2 niveles | U27: AZUL OSCURO | V27: Pereira | W27: musculación | Y27: 500000 | Z27: =IFERROR(VLOOKUP(S27,'Precios y materiales '!$A:$C,3,FALSE),"") -> 600000 | AA27: =(Y27*$AA$3)/'Mano de obra'!$C$9 -> 6.8121207 | AB27: =AA27*(1-N27) -> 0 | AC27: =AB27/9 -> 0 | AD27: =AD26+(AA27*(1-N27)) -> 134.97009 | AF27: 18 may | AG27: =IFERROR(TEXT(HLOOKUP(AD27,'Mano de obra'!$L$23:$BP$25,3,TRUE),"d mmm"),"") -> 31 May | AH27: =IF((($N27)*100)>='plan de producción'!AH$3,"x"," Material") -> x | AI27: =IF((($N27)*100)>='plan de producción'!AI$3,"x","Armar ") -> x | AJ27: =IF((($N27)*100)>='plan de producción'!AJ$3,"x"," Resoldar") -> x | AK27: =IF((($N27)*100)>='plan de producción'!AK$3,"x"," Pulir") -> x | AL27: =IF((($N27)*100)>='plan de producción'!AL$3,"x","Pintar ") -> x | AM27: =IF((($N27)*100)>='plan de producción'!AM$3,"x","Ensamblar ") -> x | AN27: =IF((($N27)*100)>='plan de producción'!AN$3,"x"," Empacar") -> x
C28: Laser | N28: 1 | P28: 24 | Q28: 984 | R28: JHON - NICOLAS | S28: XM908 | T28: rack mancuernas 2 niveles | U28: AZUL OSCURO | V28: Pereira | W28: musculación | Y28: 764000 | Z28: =IFERROR(VLOOKUP(S28,'Precios y materiales '!$A:$C,3,FALSE),"") -> 600000 | AA28: =(Y28*$AA$3)/'Mano de obra'!$C$9 -> 10.40892 | AB28: =AA28*(1-N28) -> 0 | AC28: =AB28/9 -> 0 | AD28: =AD27+(AA28*(1-N28)) -> 134.97009 | AF28: 18 may | AG28: =IFERROR(TEXT(HLOOKUP(AD28,'Mano de obra'!$L$23:$BP$25,3,TRUE),"d mmm"),"") -> 31 May | AH28: =IF((($N28)*100)>='plan de producción'!AH$3,"x"," Material") -> x | AI28: =IF((($N28)*100)>='plan de producción'!AI$3,"x","Armar ") -> x | AJ28: =IF((($N28)*100)>='plan de producción'!AJ$3,"x"," Resoldar") -> x | AK28: =IF((($N28)*100)>='plan de producción'!AK$3,"x"," Pulir") -> x | AL28: =IF((($N28)*100)>='plan de producción'!AL$3,"x","Pintar ") -> x | AM28: =IF((($N28)*100)>='plan de producción'!AM$3,"x","Ensamblar ") -> x | AN28: =IF((($N28)*100)>='plan de producción'!AN$3,"x"," Empacar") -> x
A29: Torno A. | B29: Torno E. | M29: Cojines | N29: 0.2 | P29: 25 | Q29: 8 | R29: JHON - NICOLAS | S29: XM121 | T29: Flexor | U29: AZUL OSCURO | V29: Pereira | W29: musculación | Y29: 3600000 | Z29: =IFERROR(VLOOKUP(S29,'Precios y materiales '!$A:$C,3,FALSE),"") -> 3600000 | AA29: =(Y29*$AA$3)/'Mano de obra'!$C$9 -> 49.047269 | AB29: =AA29*(1-N29) -> 39.237815 | AC29: =AB29/9 -> 4.3597573 | AD29: =AD28+(AA29*(1-N29)) -> 174.20791 | AF29: 19 may | AG29: =IFERROR(TEXT(HLOOKUP(AD29,'Mano de obra'!$L$23:$BP$25,3,TRUE),"d mmm"),"") -> 31 May | AH29: =IF((($N29)*100)>='plan de producción'!AH$3,"x"," Material") -> x | AI29: =IF((($N29)*100)>='plan de producción'!AI$3,"x","Armar ") -> Armar | AJ29: =IF((($N29)*100)>='plan de producción'!AJ$3,"x"," Resoldar") -> Resoldar | AK29: =IF((($N29)*100)>='plan de producción'!AK$3,"x"," Pulir") -> Pulir | AL29: =IF((($N29)*100)>='plan de producción'!AL$3,"x","Pintar ") -> Pintar | AM29: =IF((($N29)*100)>='plan de producción'!AM$3,"x","Ensamblar ") -> Ensamblar | AN29: =IF((($N29)*100)>='plan de producción'!AN$3,"x"," Empacar") -> Empacar
A30: Torno A. | B30: Torno E. | M30: Cojines | N30: 0.2 | P30: 26 | Q30: 7 | R30: JHON - NICOLAS | S30: XM120 | T30: Flexo Extensor | U30: AZUL OSCURO | V30: Pereira | W30: musculación | Y30: 3990000 | Z30: =IFERROR(VLOOKUP(S30,'Precios y materiales '!$A:$C,3,FALSE),"") -> 3990000 | AA30: =(Y30*$AA$3)/'Mano de obra'!$C$9 -> 54.360723 | AB30: =AA30*(1-N30) -> 43.488579 | AC30: =AB30/9 -> 4.8320643 | AD30: =AD29+(AA30*(1-N30)) -> 217.69649 | AF30: 19 may | AG30: =IFERROR(TEXT(HLOOKUP(AD30,'Mano de obra'!$L$23:$BP$25,3,TRUE),"d mmm"),"") -> 1 Jun | AH30: =IF((($N30)*100)>='plan de producción'!AH$3,"x"," Material") -> x | AI30: =IF((($N30)*100)>='plan de producción'!AI$3,"x","Armar ") -> Armar | AJ30: =IF((($N30)*100)>='plan de producción'!AJ$3,"x"," Resoldar") -> Resoldar | AK30: =IF((($N30)*100)>='plan de producción'!AK$3,"x"," Pulir") -> Pulir | AL30: =IF((($N30)*100)>='plan de producción'!AL$3,"x","Pintar ") -> Pintar | AM30: =IF((($N30)*100)>='plan de producción'!AM$3,"x","Ensamblar ") -> Ensamblar | AN30: =IF((($N30)*100)>='plan de producción'!AN$3,"x"," Empacar") -> Empacar
A31: Torno A. | B31: Torno E. | I31: Zinc | N31: 0.2 | P31: 27 | Q31: 9 | R31: JHON - NICOLAS | S31: XM170 | T31: Sentadilla Smith 2.0 | U31: AZUL OSCURO | V31: Pereira | W31: musculación | Y31: 4450000 | Z31: =IFERROR(VLOOKUP(S31,'Precios y materiales '!$A:$C,3,FALSE),"") -> 4450000 | AA31: =(Y31*$AA$3)/'Mano de obra'!$C$9 -> 60.627875 | AB31: =AA31*(1-N31) -> 48.5023 | AC31: =AB31/9 -> 5.3891444 | AD31: =AD30+(AA31*(1-N31)) -> 266.19879 | AF31: 46162 | AG31: =IFERROR(TEXT(HLOOKUP(AD31,'Mano de obra'!$L$23:$BP$25,3,TRUE),"d mmm"),"") -> 2 Jun | AH31: =IF((($N31)*100)>='plan de producción'!AH$3,"x"," Material") -> x | AI31: =IF((($N31)*100)>='plan de producción'!AI$3,"x","Armar ") -> Armar | AJ31: =IF((($N31)*100)>='plan de producción'!AJ$3,"x"," Resoldar") -> Resoldar | AK31: =IF((($N31)*100)>='plan de producción'!AK$3,"x"," Pulir") -> Pulir | AL31: =IF((($N31)*100)>='plan de producción'!AL$3,"x","Pintar ") -> Pintar | AM31: =IF((($N31)*100)>='plan de producción'!AM$3,"x","Ensamblar ") -> Ensamblar | AN31: =IF((($N31)*100)>='plan de producción'!AN$3,"x"," Empacar") -> Empacar
A32: Torno A. | B32: Torno E. | C32: Laser | I32: Zinc | M32: Cojines | N32: 0 | P32: 28 | Q32: 29 | R32: JHON - NICOLAS | S32: XM116 | T32: Elevador de pelvis | U32: AZUL OSCURO | V32: Pereira | W32: musculación | Y32: 2490000 | Z32: =IFERROR(VLOOKUP(S32,'Precios y materiales '!$A:$C,3,FALSE),"") -> 2490000 | AA32: =(Y32*$AA$3)/'Mano de obra'!$C$9 -> 33.924361 | AB32: =AA32*(1-N32) -> 33.924361 | AC32: =AB32/9 -> 3.7693735 | AD32: =AD31+(AA32*(1-N32)) -> 300.12315 | AF32: 46162 | AG32: =IFERROR(TEXT(HLOOKUP(AD32,'Mano de obra'!$L$23:$BP$25,3,TRUE),"d mmm"),"") -> 2 Jun | AH32: =IF((($N32)*100)>='plan de producción'!AH$3,"x"," Material") -> Material | AI32: =IF((($N32)*100)>='plan de producción'!AI$3,"x","Armar ") -> Armar | AJ32: =IF((($N32)*100)>='plan de producción'!AJ$3,"x"," Resoldar") -> Resoldar | AK32: =IF((($N32)*100)>='plan de producción'!AK$3,"x"," Pulir") -> Pulir | AL32: =IF((($N32)*100)>='plan de producción'!AL$3,"x","Pintar ") -> Pintar | AM32: =IF((($N32)*100)>='plan de producción'!AM$3,"x","Ensamblar ") -> Ensamblar | AN32: =IF((($N32)*100)>='plan de producción'!AN$3,"x"," Empacar") -> Empacar
A33: Torno A. | B33: Torno E. | C33: Laser | D33: Carenaje | F33: Tubos | M33: Cojines | N33: 0.4 | Q33: 985 | R33: Diosivan Paez | S33: XM129 | T33: Hammer pecho plano | U33: MORADO NEGRO | V33: Ocaña | W33: Musculación | Y33: 2520000 | Z33: =IFERROR(VLOOKUP(S33,'Precios y materiales '!$A:$C,3,FALSE),"") -> 2520000 | AA33: =(Y33*$AA$3)/'Mano de obra'!$C$9 -> 34.333089 | AB33: =AA33*(1-N33) -> 20.599853 | AC33: =AB33/9 -> 2.2888726 | AD33: =AD32+(AA33*(1-N33)) -> 320.723 | AF33: 25 may | AG33: =IFERROR(TEXT(HLOOKUP(AD33,'Mano de obra'!$L$23:$BP$25,3,TRUE),"d mmm"),"") -> 2 Jun | AH33: =IF((($N33)*100)>='plan de producción'!AH$3,"x"," Material") -> x | AI33: =IF((($N33)*100)>='plan de producción'!AI$3,"x","Armar ") -> x | AJ33: =IF((($N33)*100)>='plan de producción'!AJ$3,"x"," Resoldar") -> Resoldar | AK33: =IF((($N33)*100)>='plan de producción'!AK$3,"x"," Pulir") -> Pulir | AL33: =IF((($N33)*100)>='plan de producción'!AL$3,"x","Pintar ") -> Pintar | AM33: =IF((($N33)*100)>='plan de producción'!AM$3,"x","Ensamblar ") -> Ensamblar | AN33: =IF((($N33)*100)>='plan de producción'!AN$3,"x"," Empacar") -> Empacar
B34: Torno E. | C34: Laser | D34: Carenaje | F34: Tubos | M34: Cojines | N34: 0.8 | Q34: 986 | R34: Diosivan Paez | S34: XM105 | T34: Banco Multifunción | U34: MORADO NEGRO | V34: Ocaña | W34: Musculación | Y34: 1190000 | Z34: =IFERROR(VLOOKUP(S34,'Precios y materiales '!$A:$C,3,FALSE),"") -> 1190000 | AA34: =(Y34*$AA$3)/'Mano de obra'!$C$9 -> 16.212847 | AB34: =AA34*(1-N34) -> 3.2425695 | AC34: =AB34/9 -> 0.3602855 | AD34: =AD33+(AA34*(1-N34)) -> 323.96557 | AF34: 25 may | AG34: =IFERROR(TEXT(HLOOKUP(AD34,'Mano de obra'!$L$23:$BP$25,3,TRUE),"d mmm"),"") -> 2 Jun | AH34: =IF((($N34)*100)>='plan de producción'!AH$3,"x"," Material") -> x | AI34: =IF((($N34)*100)>='plan de producción'!AI$3,"x","Armar ") -> x | AJ34: =IF((($N34)*100)>='plan de producción'!AJ$3,"x"," Resoldar") -> x | AK34: =IF((($N34)*100)>='plan de producción'!AK$3,"x"," Pulir") -> x | AL34: =IF((($N34)*100)>='plan de producción'!AL$3,"x","Pintar ") -> x | AM34: =IF((($N34)*100)>='plan de producción'!AM$3,"x","Ensamblar ") -> Ensamblar | AN34: =IF((($N34)*100)>='plan de producción'!AN$3,"x"," Empacar") -> Empacar
A35: Torno A. | B35: Torno E. | C35: Laser | D35: Carenaje | E35: Placas | F35: Tubos | G35: Inox. | H35: Pintu. | I35: Zinc | J35: Tornillos | K35: Rodam. | M35: Cojines | N35: 0.8 | Q35: 987 | R35: Camilo Aristizabal | S35: XB457 | T35: Pasamanos para parque | U35: negro…parece | V35: Manizales | W35: Bioparques | Y35: 2680000 | Z35: =IFERROR(VLOOKUP(S35,'Precios y materiales '!$A:$C,3,FALSE),"") -> 2680000 | AA35: =(Y35*$AA$3)/'Mano de obra'!$C$9 -> 36.512967 | AB35: =AA35*(1-N35) -> 7.3025934 | AC35: =AB35/9 -> 0.81139927 | AD35: =AD34+(AA35*(1-N35)) -> 331.26816 | AF35: 25 may | AG35: =IFERROR(TEXT(HLOOKUP(AD35,'Mano de obra'!$L$23:$BP$25,3,TRUE),"d mmm"),"") -> 2 Jun | AH35: =IF((($N35)*100)>='plan de producción'!AH$3,"x"," Material") -> x | AI35: =IF((($N35)*100)>='plan de producción'!AI$3,"x","Armar ") -> x | AJ35: =IF((($N35)*100)>='plan de producción'!AJ$3,"x"," Resoldar") -> x | AK35: =IF((($N35)*100)>='plan de producción'!AK$3,"x"," Pulir") -> x | AL35: =IF((($N35)*100)>='plan de producción'!AL$3,"x","Pintar ") -> x | AM35: =IF((($N35)*100)>='plan de producción'!AM$3,"x","Ensamblar ") -> Ensamblar | AN35: =IF((($N35)*100)>='plan de producción'!AN$3,"x"," Empacar") -> Empacar
A36: Torno A. | B36: Torno E. | C36: Laser | D36: Carenaje | E36: Placas | F36: Tubos | G36: Inox. | H36: Pintu. | I36: Zinc | J36: Tornillos | K36: Rodam. | N36: 0 | Q36: 988 | R36: PETRA proyectos y construcciones | S36: xb449 | T36: =VLOOKUP(S36,'Precios y materiales '!$A$2:$B$147,2,FALSE) -> Halon de espalda con discos | U36: naraja | V36: Pereira | W36: Bioparques | Y36: 16809075 | Z36: =IFERROR(VLOOKUP(S36,'Precios y materiales '!$A:$C,3,FALSE),"") -> 3151260.5 | AA36: =(Y36*$AA$3)/'Mano de obra'!$C$9 -> 229.0109 | AB36: =AA36*(1-N36) -> 229.0109 | AC36: =AB36/9 -> 25.445655 | AD36: =AD35+(AA36*(1-N36)) -> 560.27906 | AF36: 28 may | AG36: =IFERROR(TEXT(HLOOKUP(AD36,'Mano de obra'!$L$23:$BP$25,3,TRUE),"d mmm"),"") -> 8 Jun | AH36: =IF((($N36)*100)>='plan de producción'!AH$3,"x"," Material") -> Material | AI36: =IF((($N36)*100)>='plan de producción'!AI$3,"x","Armar ") -> Armar | AJ36: =IF((($N36)*100)>='plan de producción'!AJ$3,"x"," Resoldar") -> Resoldar | AK36: =IF((($N36)*100)>='plan de producción'!AK$3,"x"," Pulir") -> Pulir | AL36: =IF((($N36)*100)>='plan de producción'!AL$3,"x","Pintar ") -> Pintar | AM36: =IF((($N36)*100)>='plan de producción'!AM$3,"x","Ensamblar ") -> Ensamblar | AN36: =IF((($N36)*100)>='plan de producción'!AN$3,"x"," Empacar") -> Empacar
A37: Torno A. | B37: Torno E. | C37: Laser | D37: Carenaje | E37: Placas | F37: Tubos | G37: Inox. | H37: Pintu. | I37: Zinc | J37: Tornillos | K37: Rodam. | N37: 0 | Q37: 989 | R37: PETRA proyectos y construcciones | S37: xb442 | T37: =VLOOKUP(S37,'Precios y materiales '!$A$2:$B$147,2,FALSE) -> Sentadilla con discos | V37: Pereira | W37: Bioparques | Y37: 3151260.5 | Z37: =IFERROR(VLOOKUP(S37,'Precios y materiales '!$A:$C,3,FALSE),"") -> 3151260.5 | AA37: =(Y37*$AA$3)/'Mano de obra'!$C$9 -> 42.933534 | AB37: =AA37*(1-N37) -> 42.933534 | AC37: =AB37/9 -> 4.7703927 | AD37: =AD36+(AA37*(1-N37)) -> 603.2126 | AF37: 29 may | AG37: =IFERROR(TEXT(HLOOKUP(AD37,'Mano de obra'!$L$23:$BP$25,3,TRUE),"d mmm"),"") -> 9 Jun | AH37: =IF((($N37)*100)>='plan de producción'!AH$3,"x"," Material") -> Material | AI37: =IF((($N37)*100)>='plan de producción'!AI$3,"x","Armar ") -> Armar | AJ37: =IF((($N37)*100)>='plan de producción'!AJ$3,"x"," Resoldar") -> Resoldar | AK37: =IF((($N37)*100)>='plan de producción'!AK$3,"x"," Pulir") -> Pulir | AL37: =IF((($N37)*100)>='plan de producción'!AL$3,"x","Pintar ") -> Pintar | AM37: =IF((($N37)*100)>='plan de producción'!AM$3,"x","Ensamblar ") -> Ensamblar | AN37: =IF((($N37)*100)>='plan de producción'!AN$3,"x"," Empacar") -> Empacar
A38: Torno A. | B38: Torno E. | C38: Laser | D38: Carenaje | E38: Placas | F38: Tubos | G38: Inox. | H38: Pintu. | I38: Zinc | J38: Tornillos | K38: Rodam. | N38: 0 | Q38: 990 | R38: PETRA proyectos y construcciones | S38: xb437 | T38: =VLOOKUP(S38,'Precios y materiales '!$A$2:$B$147,2,FALSE) -> Press de pecho con discos | V38: Pereira | W38: Bioparques | Y38: 3151260.5 | Z38: =IFERROR(VLOOKUP(S38,'Precios y materiales '!$A:$C,3,FALSE),"") -> 3151260.5 | AA38: =(Y38*$AA$3)/'Mano de obra'!$C$9 -> 42.933534 | AB38: =AA38*(1-N38) -> 42.933534 | AC38: =AB38/9 -> 4.7703927 | AD38: =AD37+(AA38*(1-N38)) -> 646.14613 | AF38: 1 jun | AG38: =IFERROR(TEXT(HLOOKUP(AD38,'Mano de obra'!$L$23:$BP$25,3,TRUE),"d mmm"),"") -> 9 Jun | AH38: =IF((($N38)*100)>='plan de producción'!AH$3,"x"," Material") -> Material | AI38: =IF((($N38)*100)>='plan de producción'!AI$3,"x","Armar ") -> Armar | AJ38: =IF((($N38)*100)>='plan de producción'!AJ$3,"x"," Resoldar") -> Resoldar | AK38: =IF((($N38)*100)>='plan de producción'!AK$3,"x"," Pulir") -> Pulir | AL38: =IF((($N38)*100)>='plan de producción'!AL$3,"x","Pintar ") -> Pintar | AM38: =IF((($N38)*100)>='plan de producción'!AM$3,"x","Ensamblar ") -> Ensamblar | AN38: =IF((($N38)*100)>='plan de producción'!AN$3,"x"," Empacar") -> Empacar
A39: Torno A. | B39: Torno E. | C39: Laser | D39: Carenaje | E39: Placas | F39: Tubos | G39: Inox. | H39: Pintu. | I39: Zinc | J39: Tornillos | K39: Rodam. | N39: 0 | Q39: 991 | R39: PETRA proyectos y construcciones | S39: xb420 | T39: =VLOOKUP(S39,'Precios y materiales '!$A$2:$B$147,2,FALSE) -> Dominadas y Fondos bio | V39: Pereira | W39: Bioparques | Y39: 1841092 | Z39: =IFERROR(VLOOKUP(S39,'Precios y materiales '!$A:$C,3,FALSE),"") -> 1841092 | AA39: =(Y39*$AA$3)/'Mano de obra'!$C$9 -> 25.083482 | AB39: =AA39*(1-N39) -> 25.083482 | AC39: =AB39/9 -> 2.7870536 | AD39: =AD38+(AA39*(1-N39)) -> 671.22961 | AF39: 1 jun | AG39: =IFERROR(TEXT(HLOOKUP(AD39,'Mano de obra'!$L$23:$BP$25,3,TRUE),"d mmm"),"") -> 9 Jun | AH39: =IF((($N39)*100)>='plan de producción'!AH$3,"x"," Material") -> Material | AI39: =IF((($N39)*100)>='plan de producción'!AI$3,"x","Armar ") -> Armar | AJ39: =IF((($N39)*100)>='plan de producción'!AJ$3,"x"," Resoldar") -> Resoldar | AK39: =IF((($N39)*100)>='plan de producción'!AK$3,"x"," Pulir") -> Pulir | AL39: =IF((($N39)*100)>='plan de producción'!AL$3,"x","Pintar ") -> Pintar | AM39: =IF((($N39)*100)>='plan de producción'!AM$3,"x","Ensamblar ") -> Ensamblar | AN39: =IF((($N39)*100)>='plan de producción'!AN$3,"x"," Empacar") -> Empacar
A40: Torno A. | B40: Torno E. | C40: Laser | D40: Carenaje | E40: Placas | F40: Tubos | G40: Inox. | H40: Pintu. | I40: Zinc | J40: Tornillos | K40: Rodam. | N40: 0 | Q40: 992 | R40: PETRA proyectos y construcciones | S40: xb402 | T40: =VLOOKUP(S40,'Precios y materiales '!$A$2:$B$147,2,FALSE) -> Banco Abdominal doble | V40: Pereira | W40: Bioparques | Y40: 2484790 | Z40: =IFERROR(VLOOKUP(S40,'Precios y materiales '!$A:$C,3,FALSE),"") -> 2484790 | AA40: =(Y40*$AA$3)/'Mano de obra'!$C$9 -> 33.853379 | AB40: =AA40*(1-N40) -> 33.853379 | AC40: =AB40/9 -> 3.7614866 | AD40: =AD39+(AA40*(1-N40)) -> 705.08299 | AF40: 2 jun | AG40: =IFERROR(TEXT(HLOOKUP(AD40,'Mano de obra'!$L$23:$BP$25,3,TRUE),"d mmm"),"") -> 10 Jun | AH40: =IF((($N40)*100)>='plan de producción'!AH$3,"x"," Material") -> Material | AI40: =IF((($N40)*100)>='plan de producción'!AI$3,"x","Armar ") -> Armar | AJ40: =IF((($N40)*100)>='plan de producción'!AJ$3,"x"," Resoldar") -> Resoldar | AK40: =IF((($N40)*100)>='plan de producción'!AK$3,"x"," Pulir") -> Pulir | AL40: =IF((($N40)*100)>='plan de producción'!AL$3,"x","Pintar ") -> Pintar | AM40: =IF((($N40)*100)>='plan de producción'!AM$3,"x","Ensamblar ") -> Ensamblar | AN40: =IF((($N40)*100)>='plan de producción'!AN$3,"x"," Empacar") -> Empacar
...

Sheet Mano de obra
E1: 2026 | K1: l | L1: v | M1: s | N1: d | O1: l | P1: m | Q1: w | R1: j | S1: v | T1: s | U1: d | V1: l | W1: m | X1: w | Y1: j | Z1: v | AA1: s | AB1: d | AC1: l | AD1: m | AE1: w | AF1: j | AG1: v | AH1: s | AI1: d | AJ1: l | AK1: m | AL1: w | AM1: j | AN1: v | AO1: s | AP1: d | AQ1: l | AR1: m | AS1: w | AT1: j | AU1: v | AV1: s | AW1: d | AX1: l | AY1: m | AZ1: w | BA1: j | BB1: v | BC1: s | BD1: d | BE1: l | BF1: m | BG1: w | BH1: j | BI1: v | BJ1: s | BK1: d | BL1: l | BM1: m | BN1: w | BO1: j | BP1: v
E2: EMPLEADO | G2: Salario base | H2: BONIF | I2: Costo total | L2: 1 | M2: 2 | N2: 3 | O2: 4 | P2: 5 | Q2: 6 | R2: 7 | S2: 8 | T2: 9 | U2: 10 | V2: 11 | W2: 12 | X2: 13 | Y2: 14 | Z2: 15 | AA2: 16 | AB2: 17 | AC2: 18 | AD2: 19 | AE2: 20 | AF2: 21 | AG2: 22 | AH2: 23 | AI2: 24 | AJ2: 25 | AK2: 26 | AL2: 27 | AM2: 28 | AN2: 29 | AO2: 30 | AP2: 31 | AQ2: 32 | AR2: 33 | AS2: 34 | AT2: 35 | AU2: 36 | AV2: 37 | AW2: 38 | AX2: 39 | AY2: 40 | AZ2: 41 | BA2: 42 | BB2: 43 | BC2: 44 | BD2: 45 | BE2: 46 | BF2: 47 | BG2: 48 | BH2: 49 | BI2: 50 | BJ2: 51 | BK2: 52 | BL2: 53 | BM2: 54 | BN2: 55 | BO2: 56 | BP2: 57
E3: Nelly Muñoz Arias | F3: Ventas | G3: 3500000 | I3: =G3+H3 -> 3500000 | J3: 1 | L3: 1 | M3: 2 | N3: 3 | O3: 4 | P3: 5 | Q3: 6 | R3: 7 | S3: 8 | T3: 9 | U3: 10 | V3: 11 | W3: 12 | X3: 13 | Y3: 14 | Z3: 15 | AA3: 16 | AB3: 17 | AC3: 18 | AD3: 19 | AE3: 20 | AF3: 21 | AG3: 22 | AH3: 23 | AI3: 24 | AJ3: 25 | AK3: 26 | AL3: 27 | AM3: 28 | AN3: 29 | AO3: 30 | AP3: 31 | AQ3: 32 | AR3: 33 | AS3: 34 | AT3: 35 | AU3: 36 | AV3: 37 | AW3: 38 | AX3: 39 | AY3: 40 | AZ3: 41 | BA3: 42 | BB3: 43 | BC3: 44 | BD3: 45 | BE3: 46 | BF3: 47 | BG3: 48 | BH3: 49 | BI3: 50 | BJ3: 51 | BK3: 52 | BL3: 53 | BM3: 54 | BN3: 55 | BO3: 56 | BP3: 57
E4: Ana Maria Ramirez Torres | F4: Administración | G4: 950000 | I4: =G4+H4 -> 950000 | J4: 1
E5: Gina Lorena Lotero | F5: Administración | G5: 1750905 | H5: 400000 | I5: =G5+H5 -> 2150905 | J5: 14
E6: Santiago Alejandro Cardona | G6: 1750905 | I6: =G6+H6 -> 1750905
E7: TOTAL EMPLEADOS ADM+VTAS | F7: =COUNTIF(G3:G5,">0") -> 3 | G7: =SUM(G3:G5) -> 6200905 | I7: =(SUM(G3:H6))*(1+B12) -> 14365113
J8: Vacas debe sacar
A9: Costo por persona | B9: HORA | C9: =C14/C16 -> 22019.574 | D9: 1 | E9: Juan Felipe Martinez Aristizabal | F9: Armador | G9: 1750905 | H9: 1000000 | I9: =G9+H9 -> 2750905 | J9: 8 | K9: =(I9*(1+$B$12))/$C$16 -> 25034.691 | M9: =IF($E9="","",IF(OR(M$1="s",M$1="d"),"",IF(M$25<TODAY(),"",IF(M$1="v",6,9)))) | N9: =IF($E9="","",IF(OR(N$1="s",N$1="d"),"",IF(N$25<TODAY(),"",IF(N$1="v",6,9)))) | O9: =IF($E9="","",IF(OR(O$1="s",O$1="d"),"",IF(O$25<TODAY(),"",IF(O$1="v",6,9)))) | P9: =IF($E9="","",IF(OR(P$1="s",P$1="d"),"",IF(P$25<TODAY(),"",IF(P$1="v",6,9)))) | Q9: =IF($E9="","",IF(OR(Q$1="s",Q$1="d"),"",IF(Q$25<TODAY(),"",IF(Q$1="v",6,9)))) | R9: =IF($E9="","",IF(OR(R$1="s",R$1="d"),"",IF(R$25<TODAY(),"",IF(R$1="v",6,9)))) | S9: =IF($E9="","",IF(OR(S$1="s",S$1="d"),"",IF(S$25<TODAY(),"",IF(S$1="v",6,9)))) | T9: =IF($E9="","",IF(OR(T$1="s",T$1="d"),"",IF(T$25<TODAY(),"",IF(T$1="v",6,9)))) | ... W9: =IF($E9="","",IF(OR(W$1="s",W$1="d"),"",IF(W$25<TODAY(),"",IF(W$1="v",6,9)))) | AA9: =IF($E9="","",IF(OR(AA$1="s",AA$1="d"),"",IF(AA$25<TODAY(),"",IF(AA$1="v",6,9)))) | AB9: =IF($E9="","",IF(OR(AB$1="s",AB$1="d"),"",IF(AB$25<TODAY(),"",IF(AB$1="v",6,9)))) | AD9: =IF($E9="","",IF(OR(AD$1="s",AD$1="d"),"",IF(AD$25<TODAY(),"",IF(AD$1="v",6,9)))) | AE9: =IF($E9="","",IF(OR(AE$1="s",AE$1="d"),"",IF(AE$25<TODAY(),"",IF(AE$1="v",6,9)))) | AF9: =IF($E9="","",IF(OR(AF$1="s",AF$1="d"),"",IF(AF$25<TODAY(),"",IF(AF$1="v",6,9)))) | AG9: =IF($E9="","",IF(OR(AG$1="s",AG$1="d"),"",IF(AG$25<TODAY(),"",IF(AG$1="v",6,9)))) | AH9: =IF($E9="","",IF(OR(AH$1="s",AH$1="d"),"",IF(AH$25<TODAY(),"",IF(AH$1="v",6,9)))) | AI9: =IF($E9="","",IF(OR(AI$1="s",AI$1="d"),"",IF(AI$25<TODAY(),"",IF(AI$1="v",6,9)))) | AJ9: =IF($E9="","",IF(OR(AJ$1="s",AJ$1="d"),"",IF(AJ$25<TODAY(),"",IF(AJ$1="v",6,9)))) | AK9: =IF($E9="","",IF(OR(AK$1="s",AK$1="d"),"",IF(AK$25<TODAY(),"",IF(AK$1="v",6,9)))) | ... BP9: =IF($E9="","",IF(OR(BP$1="s",BP$1="d"),"",IF(BP$25<TODAY(),"",IF(BP$1="v",6,9)))) -> 6
A10: Costo por persona | B10: DIA | C10: =C14/C15 -> 208084.98 | D10: 2 | E10: Cristian Camilo Rodriguez Giraldo | F10: Tornero | G10: 1750905 | H10: 640000 | I10: =G10+H10 -> 2390905 | J10: 23 | K10: =(I10*(1+$B$12))/$C$16 -> 21758.501 | M10: =IF($E10="","",IF(OR(M$1="s",M$1="d"),"",IF(M$25<TODAY(),"",IF(M$1="v",6,9)))) | N10: =IF($E10="","",IF(OR(N$1="s",N$1="d"),"",IF(N$25<TODAY(),"",IF(N$1="v",6,9)))) | O10: =IF($E10="","",IF(OR(O$1="s",O$1="d"),"",IF(O$25<TODAY(),"",IF(O$1="v",6,9)))) | P10: =IF($E10="","",IF(OR(P$1="s",P$1="d"),"",IF(P$25<TODAY(),"",IF(P$1="v",6,9)))) | Q10: =IF($E10="","",IF(OR(Q$1="s",Q$1="d"),"",IF(Q$25<TODAY(),"",IF(Q$1="v",6,9)))) | R10: =IF($E10="","",IF(OR(R$1="s",R$1="d"),"",IF(R$25<TODAY(),"",IF(R$1="v",6,9)))) | S10: =IF($E10="","",IF(OR(S$1="s",S$1="d"),"",IF(S$25<TODAY(),"",IF(S$1="v",6,9)))) | T10: =IF($E10="","",IF(OR(T$1="s",T$1="d"),"",IF(T$25<TODAY(),"",IF(T$1="v",6,9)))) | ... AB10: =IF($E10="","",IF(OR(AB$1="s",AB$1="d"),"",IF(AB$25<TODAY(),"",IF(AB$1="v",6,9)))) | AD10: =IF($E10="","",IF(OR(AD$1="s",AD$1="d"),"",IF(AD$25<TODAY(),"",IF(AD$1="v",6,9)))) | AE10: =IF($E10="","",IF(OR(AE$1="s",AE$1="d"),"",IF(AE$25<TODAY(),"",IF(AE$1="v",6,9)))) | AF10: =IF($E10="","",IF(OR(AF$1="s",AF$1="d"),"",IF(AF$25<TODAY(),"",IF(AF$1="v",6,9)))) | AG10: =IF($E10="","",IF(OR(AG$1="s",AG$1="d"),"",IF(AG$25<TODAY(),"",IF(AG$1="v",6,9)))) | AH10: =IF($E10="","",IF(OR(AH$1="s",AH$1="d"),"",IF(AH$25<TODAY(),"",IF(AH$1="v",6,9)))) | AI10: =IF($E10="","",IF(OR(AI$1="s",AI$1="d"),"",IF(AI$25<TODAY(),"",IF(AI$1="v",6,9)))) | AJ10: =IF($E10="","",IF(OR(AJ$1="s",AJ$1="d"),"",IF(AJ$25<TODAY(),"",IF(AJ$1="v",6,9)))) | AK10: =IF($E10="","",IF(OR(AK$1="s",AK$1="d"),"",IF(AK$25<TODAY(),"",IF(AK$1="v",6,9)))) | ... BP10: =IF($E10="","",IF(OR(BP$1="s",BP$1="d"),"",IF(BP$25<TODAY(),"",IF(BP$1="v",6,9)))) -> 6
A11: Valor nomina PLANTA: | C11: =G23 -> 21776335 | D11: 3 | E11: Luis Alfonso Betancurth Osorio | F11: Pintor | G11: 1750905 | H11: 380000 | I11: =G11+H11 -> 2130905 | J11: 37 | K11: =(I11*(1+$B$12))/$C$16 -> 19392.363 | M11: =IF($E11="","",IF(OR(M$1="s",M$1="d"),"",IF(M$25<TODAY(),"",IF(M$1="v",6,9)))) | N11: =IF($E11="","",IF(OR(N$1="s",N$1="d"),"",IF(N$25<TODAY(),"",IF(N$1="v",6,9)))) | O11: =IF($E11="","",IF(OR(O$1="s",O$1="d"),"",IF(O$25<TODAY(),"",IF(O$1="v",6,9)))) | P11: =IF($E11="","",IF(OR(P$1="s",P$1="d"),"",IF(P$25<TODAY(),"",IF(P$1="v",6,9)))) | Q11: =IF($E11="","",IF(OR(Q$1="s",Q$1="d"),"",IF(Q$25<TODAY(),"",IF(Q$1="v",6,9)))) | R11: =IF($E11="","",IF(OR(R$1="s",R$1="d"),"",IF(R$25<TODAY(),"",IF(R$1="v",6,9)))) | S11: =IF($E11="","",IF(OR(S$1="s",S$1="d"),"",IF(S$25<TODAY(),"",IF(S$1="v",6,9)))) | T11: =IF($E11="","",IF(OR(T$1="s",T$1="d"),"",IF(T$25<TODAY(),"",IF(T$1="v",6,9)))) | ... AB11: =IF($E11="","",IF(OR(AB$1="s",AB$1="d"),"",IF(AB$25<TODAY(),"",IF(AB$1="v",6,9)))) | AD11: =IF($E11="","",IF(OR(AD$1="s",AD$1="d"),"",IF(AD$25<TODAY(),"",IF(AD$1="v",6,9)))) | AE11: =IF($E11="","",IF(OR(AE$1="s",AE$1="d"),"",IF(AE$25<TODAY(),"",IF(AE$1="v",6,9)))) | AF11: =IF($E11="","",IF(OR(AF$1="s",AF$1="d"),"",IF(AF$25<TODAY(),"",IF(AF$1="v",6,9)))) | AG11: =IF($E11="","",IF(OR(AG$1="s",AG$1="d"),"",IF(AG$25<TODAY(),"",IF(AG$1="v",6,9)))) | AH11: =IF($E11="","",IF(OR(AH$1="s",AH$1="d"),"",IF(AH$25<TODAY(),"",IF(AH$1="v",6,9)))) | AI11: =IF($E11="","",IF(OR(AI$1="s",AI$1="d"),"",IF(AI$25<TODAY(),"",IF(AI$1="v",6,9)))) | AJ11: =IF($E11="","",IF(OR(AJ$1="s",AJ$1="d"),"",IF(AJ$25<TODAY(),"",IF(AJ$1="v",6,9)))) | AK11: =IF($E11="","",IF(OR(AK$1="s",AK$1="d"),"",IF(AK$25<TODAY(),"",IF(AK$1="v",6,9)))) | ... BP11: =IF($E11="","",IF(OR(BP$1="s",BP$1="d"),"",IF(BP$25<TODAY(),"",IF(BP$1="v",6,9)))) -> 6
A12: Mas prestac. del : | B12: 0.72 | C12: =C11*(1+B12) -> 37455296 | D12: 4 | E12: Ariel Valencia Mina | F12: Varios | G12: 1750905 | H12: 200000 | I12: =G12+H12 -> 1950905 | J12: 9 | K12: =(I12*(1+$B$12))/$C$16 -> 17754.268 | M12: =IF($E12="","",IF(OR(M$1="s",M$1="d"),"",IF(M$25<TODAY(),"",IF(M$1="v",6,9)))) | N12: =IF($E12="","",IF(OR(N$1="s",N$1="d"),"",IF(N$25<TODAY(),"",IF(N$1="v",6,9)))) | O12: =IF($E12="","",IF(OR(O$1="s",O$1="d"),"",IF(O$25<TODAY(),"",IF(O$1="v",6,9)))) | P12: =IF($E12="","",IF(OR(P$1="s",P$1="d"),"",IF(P$25<TODAY(),"",IF(P$1="v",6,9)))) | Q12: =IF($E12="","",IF(OR(Q$1="s",Q$1="d"),"",IF(Q$25<TODAY(),"",IF(Q$1="v",6,9)))) | R12: =IF($E12="","",IF(OR(R$1="s",R$1="d"),"",IF(R$25<TODAY(),"",IF(R$1="v",6,9)))) | S12: =IF($E12="","",IF(OR(S$1="s",S$1="d"),"",IF(S$25<TODAY(),"",IF(S$1="v",6,9)))) | T12: =IF($E12="","",IF(OR(T$1="s",T$1="d"),"",IF(T$25<TODAY(),"",IF(T$1="v",6,9)))) | ... AB12: =IF($E12="","",IF(OR(AB$1="s",AB$1="d"),"",IF(AB$25<TODAY(),"",IF(AB$1="v",6,9)))) | AD12: =IF($E12="","",IF(OR(AD$1="s",AD$1="d"),"",IF(AD$25<TODAY(),"",IF(AD$1="v",6,9)))) | AE12: =IF($E12="","",IF(OR(AE$1="s",AE$1="d"),"",IF(AE$25<TODAY(),"",IF(AE$1="v",6,9)))) | AF12: =IF($E12="","",IF(OR(AF$1="s",AF$1="d"),"",IF(AF$25<TODAY(),"",IF(AF$1="v",6,9)))) | AG12: =IF($E12="","",IF(OR(AG$1="s",AG$1="d"),"",IF(AG$25<TODAY(),"",IF(AG$1="v",6,9)))) | AH12: =IF($E12="","",IF(OR(AH$1="s",AH$1="d"),"",IF(AH$25<TODAY(),"",IF(AH$1="v",6,9)))) | AI12: =IF($E12="","",IF(OR(AI$1="s",AI$1="d"),"",IF(AI$25<TODAY(),"",IF(AI$1="v",6,9)))) | AJ12: =IF($E12="","",IF(OR(AJ$1="s",AJ$1="d"),"",IF(AJ$25<TODAY(),"",IF(AJ$1="v",6,9)))) | AK12: =IF($E12="","",IF(OR(AK$1="s",AK$1="d"),"",IF(AK$25<TODAY(),"",IF(AK$1="v",6,9)))) | ... BP12: =IF($E12="","",IF(OR(BP$1="s",BP$1="d"),"",IF(BP$25<TODAY(),"",IF(BP$1="v",6,9)))) -> 6
A13: Cantidad empleados planta: | C13: =F23 -> 9 | D13: 5 | E13: Daniel Garcia Zaray | F13: Ensamblador | G13: 1750905 | H13: 300000 | I13: =G13+H13 -> 2050905 | J13: 8 | K13: =(I13*(1+$B$12))/$C$16 -> 18664.321 | M13: =IF($E13="","",IF(OR(M$1="s",M$1="d"),"",IF(M$25<TODAY(),"",IF(M$1="v",6,9)))) | N13: =IF($E13="","",IF(OR(N$1="s",N$1="d"),"",IF(N$25<TODAY(),"",IF(N$1="v",6,9)))) | O13: =IF($E13="","",IF(OR(O$1="s",O$1="d"),"",IF(O$25<TODAY(),"",IF(O$1="v",6,9)))) | P13: =IF($E13="","",IF(OR(P$1="s",P$1="d"),"",IF(P$25<TODAY(),"",IF(P$1="v",6,9)))) | Q13: =IF($E13="","",IF(OR(Q$1="s",Q$1="d"),"",IF(Q$25<TODAY(),"",IF(Q$1="v",6,9)))) | R13: =IF($E13="","",IF(OR(R$1="s",R$1="d"),"",IF(R$25<TODAY(),"",IF(R$1="v",6,9)))) | S13: =IF($E13="","",IF(OR(S$1="s",S$1="d"),"",IF(S$25<TODAY(),"",IF(S$1="v",6,9)))) | T13: =IF($E13="","",IF(OR(T$1="s",T$1="d"),"",IF(T$25<TODAY(),"",IF(T$1="v",6,9)))) | ... AB13: =IF($E13="","",IF(OR(AB$1="s",AB$1="d"),"",IF(AB$25<TODAY(),"",IF(AB$1="v",6,9)))) | AD13: =IF($E13="","",IF(OR(AD$1="s",AD$1="d"),"",IF(AD$25<TODAY(),"",IF(AD$1="v",6,9)))) | AE13: =IF($E13="","",IF(OR(AE$1="s",AE$1="d"),"",IF(AE$25<TODAY(),"",IF(AE$1="v",6,9)))) | AF13: =IF($E13="","",IF(OR(AF$1="s",AF$1="d"),"",IF(AF$25<TODAY(),"",IF(AF$1="v",6,9)))) | AG13: =IF($E13="","",IF(OR(AG$1="s",AG$1="d"),"",IF(AG$25<TODAY(),"",IF(AG$1="v",6,9)))) | AH13: =IF($E13="","",IF(OR(AH$1="s",AH$1="d"),"",IF(AH$25<TODAY(),"",IF(AH$1="v",6,9)))) | AI13: =IF($E13="","",IF(OR(AI$1="s",AI$1="d"),"",IF(AI$25<TODAY(),"",IF(AI$1="v",6,9)))) | AJ13: =IF($E13="","",IF(OR(AJ$1="s",AJ$1="d"),"",IF(AJ$25<TODAY(),"",IF(AJ$1="v",6,9)))) | AK13: =IF($E13="","",IF(OR(AK$1="s",AK$1="d"),"",IF(AK$25<TODAY(),"",IF(AK$1="v",6,9)))) | ... BP13: =IF($E13="","",IF(OR(BP$1="s",BP$1="d"),"",IF(BP$25<TODAY(),"",IF(BP$1="v",6,9)))) -> 6
A14: Sueldo integral promedio planta: | C14: =C12/C13 -> 4161699.6 | D14: 6 | E14: Daniel Rodrigo Duque Zapata | F14: asist ensamble | G14: 1750905 | H14: 200000 | I14: =G14+H14 -> 1950905 | J14: 9 | K14: =(I14*(1+$B$12))/$C$16 -> 17754.268 | M14: =IF($E14="","",IF(OR(M$1="s",M$1="d"),"",IF(M$25<TODAY(),"",IF(M$1="v",6,9)))) | N14: =IF($E14="","",IF(OR(N$1="s",N$1="d"),"",IF(N$25<TODAY(),"",IF(N$1="v",6,9)))) | O14: =IF($E14="","",IF(OR(O$1="s",O$1="d"),"",IF(O$25<TODAY(),"",IF(O$1="v",6,9)))) | P14: =IF($E14="","",IF(OR(P$1="s",P$1="d"),"",IF(P$25<TODAY(),"",IF(P$1="v",6,9)))) | Q14: =IF($E14="","",IF(OR(Q$1="s",Q$1="d"),"",IF(Q$25<TODAY(),"",IF(Q$1="v",6,9)))) | R14: =IF($E14="","",IF(OR(R$1="s",R$1="d"),"",IF(R$25<TODAY(),"",IF(R$1="v",6,9)))) | S14: =IF($E14="","",IF(OR(S$1="s",S$1="d"),"",IF(S$25<TODAY(),"",IF(S$1="v",6,9)))) | T14: =IF($E14="","",IF(OR(T$1="s",T$1="d"),"",IF(T$25<TODAY(),"",IF(T$1="v",6,9)))) | ... AB14: =IF($E14="","",IF(OR(AB$1="s",AB$1="d"),"",IF(AB$25<TODAY(),"",IF(AB$1="v",6,9)))) | AD14: =IF($E14="","",IF(OR(AD$1="s",AD$1="d"),"",IF(AD$25<TODAY(),"",IF(AD$1="v",6,9)))) | AE14: =IF($E14="","",IF(OR(AE$1="s",AE$1="d"),"",IF(AE$25<TODAY(),"",IF(AE$1="v",6,9)))) | AF14: =IF($E14="","",IF(OR(AF$1="s",AF$1="d"),"",IF(AF$25<TODAY(),"",IF(AF$1="v",6,9)))) | AG14: =IF($E14="","",IF(OR(AG$1="s",AG$1="d"),"",IF(AG$25<TODAY(),"",IF(AG$1="v",6,9)))) | AH14: =IF($E14="","",IF(OR(AH$1="s",AH$1="d"),"",IF(AH$25<TODAY(),"",IF(AH$1="v",6,9)))) | AI14: =IF($E14="","",IF(OR(AI$1="s",AI$1="d"),"",IF(AI$25<TODAY(),"",IF(AI$1="v",6,9)))) | AJ14: =IF($E14="","",IF(OR(AJ$1="s",AJ$1="d"),"",IF(AJ$25<TODAY(),"",IF(AJ$1="v",6,9)))) | AK14: =IF($E14="","",IF(OR(AK$1="s",AK$1="d"),"",IF(AK$25<TODAY(),"",IF(AK$1="v",6,9)))) | ... BP14: =IF($E14="","",IF(OR(BP$1="s",BP$1="d"),"",IF(BP$25<TODAY(),"",IF(BP$1="v",6,9)))) -> 6
A15: Dias laborales en: | C15: 20 | D15: 7 | E15: Jose Fernando Gaviria | F15: Armador | H15: 3500000 | I15: =G15+H15 -> 3500000 | K15: =(I15*(1+$B$12))/$C$16 -> 31851.852 | M15: =IF($E15="","",IF(OR(M$1="s",M$1="d"),"",IF(M$25<TODAY(),"",IF(M$1="v",6,9)))) | N15: =IF($E15="","",IF(OR(N$1="s",N$1="d"),"",IF(N$25<TODAY(),"",IF(N$1="v",6,9)))) | O15: =IF($E15="","",IF(OR(O$1="s",O$1="d"),"",IF(O$25<TODAY(),"",IF(O$1="v",6,9)))) | P15: =IF($E15="","",IF(OR(P$1="s",P$1="d"),"",IF(P$25<TODAY(),"",IF(P$1="v",6,9)))) | Q15: =IF($E15="","",IF(OR(Q$1="s",Q$1="d"),"",IF(Q$25<TODAY(),"",IF(Q$1="v",6,9)))) | R15: =IF($E15="","",IF(OR(R$1="s",R$1="d"),"",IF(R$25<TODAY(),"",IF(R$1="v",6,9)))) | S15: =IF($E15="","",IF(OR(S$1="s",S$1="d"),"",IF(S$25<TODAY(),"",IF(S$1="v",6,9)))) | T15: =IF($E15="","",IF(OR(T$1="s",T$1="d"),"",IF(T$25<TODAY(),"",IF(T$1="v",6,9)))) | ... AB15: =IF($E15="","",IF(OR(AB$1="s",AB$1="d"),"",IF(AB$25<TODAY(),"",IF(AB$1="v",6,9)))) | AD15: =IF($E15="","",IF(OR(AD$1="s",AD$1="d"),"",IF(AD$25<TODAY(),"",IF(AD$1="v",6,9)))) | AE15: =IF($E15="","",IF(OR(AE$1="s",AE$1="d"),"",IF(AE$25<TODAY(),"",IF(AE$1="v",6,9)))) | AF15: =IF($E15="","",IF(OR(AF$1="s",AF$1="d"),"",IF(AF$25<TODAY(),"",IF(AF$1="v",6,9)))) | AG15: =IF($E15="","",IF(OR(AG$1="s",AG$1="d"),"",IF(AG$25<TODAY(),"",IF(AG$1="v",6,9)))) | AH15: =IF($E15="","",IF(OR(AH$1="s",AH$1="d"),"",IF(AH$25<TODAY(),"",IF(AH$1="v",6,9)))) | AI15: =IF($E15="","",IF(OR(AI$1="s",AI$1="d"),"",IF(AI$25<TODAY(),"",IF(AI$1="v",6,9)))) | AJ15: =IF($E15="","",IF(OR(AJ$1="s",AJ$1="d"),"",IF(AJ$25<TODAY(),"",IF(AJ$1="v",6,9)))) | AK15: =IF($E15="","",IF(OR(AK$1="s",AK$1="d"),"",IF(AK$25<TODAY(),"",IF(AK$1="v",6,9)))) | ... BP15: =IF($E15="","",IF(OR(BP$1="s",BP$1="d"),"",IF(BP$25<TODAY(),"",IF(BP$1="v",6,9)))) -> 6
A16: Horas laborales x persona mes promedio 2025: | C16: 189 | D16: 8 | E16: Germán | F16: Armador | G16: 1750905 | H16: 300000 | I16: =G16+H16 -> 2050905 | J16: 4 | K16: =(I16*(1+$B$12))/$C$16 -> 18664.321 | M16: =IF($E16="","",IF(OR(M$1="s",M$1="d"),"",IF(M$25<TODAY(),"",IF(M$1="v",6,9)))) | N16: =IF($E16="","",IF(OR(N$1="s",N$1="d"),"",IF(N$25<TODAY(),"",IF(N$1="v",6,9)))) | O16: =IF($E16="","",IF(OR(O$1="s",O$1="d"),"",IF(O$25<TODAY(),"",IF(O$1="v",6,9)))) | P16: =IF($E16="","",IF(OR(P$1="s",P$1="d"),"",IF(P$25<TODAY(),"",IF(P$1="v",6,9)))) | Q16: =IF($E16="","",IF(OR(Q$1="s",Q$1="d"),"",IF(Q$25<TODAY(),"",IF(Q$1="v",6,9)))) | R16: =IF($E16="","",IF(OR(R$1="s",R$1="d"),"",IF(R$25<TODAY(),"",IF(R$1="v",6,9)))) | S16: =IF($E16="","",IF(OR(S$1="s",S$1="d"),"",IF(S$25<TODAY(),"",IF(S$1="v",6,9)))) | T16: =IF($E16="","",IF(OR(T$1="s",T$1="d"),"",IF(T$25<TODAY(),"",IF(T$1="v",6,9)))) | ... AB16: =IF($E16="","",IF(OR(AB$1="s",AB$1="d"),"",IF(AB$25<TODAY(),"",IF(AB$1="v",6,9)))) | AD16: =IF($E16="","",IF(OR(AD$1="s",AD$1="d"),"",IF(AD$25<TODAY(),"",IF(AD$1="v",6,9)))) | AE16: =IF($E16="","",IF(OR(AE$1="s",AE$1="d"),"",IF(AE$25<TODAY(),"",IF(AE$1="v",6,9)))) | AF16: =IF($E16="","",IF(OR(AF$1="s",AF$1="d"),"",IF(AF$25<TODAY(),"",IF(AF$1="v",6,9)))) | AG16: =IF($E16="","",IF(OR(AG$1="s",AG$1="d"),"",IF(AG$25<TODAY(),"",IF(AG$1="v",6,9)))) | AH16: =IF($E16="","",IF(OR(AH$1="s",AH$1="d"),"",IF(AH$25<TODAY(),"",IF(AH$1="v",6,9)))) | AI16: =IF($E16="","",IF(OR(AI$1="s",AI$1="d"),"",IF(AI$25<TODAY(),"",IF(AI$1="v",6,9)))) | AJ16: =IF($E16="","",IF(OR(AJ$1="s",AJ$1="d"),"",IF(AJ$25<TODAY(),"",IF(AJ$1="v",6,9)))) | AK16: =IF($E16="","",IF(OR(AK$1="s",AK$1="d"),"",IF(AK$25<TODAY(),"",IF(AK$1="v",6,9)))) | ... BP16: =IF($E16="","",IF(OR(BP$1="s",BP$1="d"),"",IF(BP$25<TODAY(),"",IF(BP$1="v",6,9)))) -> 6
D17: 9 | E17: Santiago Cardenas | F17: Armador | H17: 3000000 | I17: =G17+H17 -> 3000000 | K17: =(I17*(1+$B$12))/$C$16 -> 27301.587
K18: =(I18*(1+$B$12))/$C$16 -> 0 | L18: =IF($E18="","",IF(OR(L$1="s",L$1="d"),"",IF(L$25<TODAY(),"",IF(L$1="v",6,9)))) | M18: =IF($E18="","",IF(OR(M$1="s",M$1="d"),"",IF(M$25<TODAY(),"",IF(M$1="v",6,9)))) | N18: =IF($E18="","",IF(OR(N$1="s",N$1="d"),"",IF(N$25<TODAY(),"",IF(N$1="v",6,9)))) | O18: =IF($E18="","",IF(OR(O$1="s",O$1="d"),"",IF(O$25<TODAY(),"",IF(O$1="v",6,9)))) | P18: =IF($E18="","",IF(OR(P$1="s",P$1="d"),"",IF(P$25<TODAY(),"",IF(P$1="v",6,9)))) | Q18: =IF($E18="","",IF(OR(Q$1="s",Q$1="d"),"",IF(Q$25<TODAY(),"",IF(Q$1="v",6,9)))) | R18: =IF($E18="","",IF(OR(R$1="s",R$1="d"),"",IF(R$25<TODAY(),"",IF(R$1="v",6,9)))) | S18: =IF($E18="","",IF(OR(S$1="s",S$1="d"),"",IF(S$25<TODAY(),"",IF(S$1="v",6,9)))) | ... AB18: =IF($E18="","",IF(OR(AB$1="s",AB$1="d"),"",IF(AB$25<TODAY(),"",IF(AB$1="v",6,9)))) | AD18: =IF($E18="","",IF(OR(AD$1="s",AD$1="d"),"",IF(AD$25<TODAY(),"",IF(AD$1="v",6,9)))) | AE18: =IF($E18="","",IF(OR(AE$1="s",AE$1="d"),"",IF(AE$25<TODAY(),"",IF(AE$1="v",6,9)))) | AF18: =IF($E18="","",IF(OR(AF$1="s",AF$1="d"),"",IF(AF$25<TODAY(),"",IF(AF$1="v",6,9)))) | AG18: =IF($E18="","",IF(OR(AG$1="s",AG$1="d"),"",IF(AG$25<TODAY(),"",IF(AG$1="v",6,9)))) | AH18: =IF($E18="","",IF(OR(AH$1="s",AH$1="d"),"",IF(AH$25<TODAY(),"",IF(AH$1="v",6,9)))) | AI18: =IF($E18="","",IF(OR(AI$1="s",AI$1="d"),"",IF(AI$25<TODAY(),"",IF(AI$1="v",6,9)))) | AJ18: =IF($E18="","",IF(OR(AJ$1="s",AJ$1="d"),"",IF(AJ$25<TODAY(),"",IF(AJ$1="v",6,9)))) | AK18: =IF($E18="","",IF(OR(AK$1="s",AK$1="d"),"",IF(AK$25<TODAY(),"",IF(AK$1="v",6,9)))) | ... BP18: =IF($E18="","",IF(OR(BP$1="s",BP$1="d"),"",IF(BP$25<TODAY(),"",IF(BP$1="v",6,9))))
